Failure # 1 (occurred at 2025-05-20_17-45-19)
[36mray::ImplicitFunc.train()[39m (pid=6657, ip=10.0.0.10, actor_id=f587f7c2170c24c75cfa34b401000000, repr=train)
           ^^^^^^^^^^^^^^^^^^^^^^^^^^^^^^^^^^^^
           ^^^^^^^^^^^^^^^^^^^^^^^^^^^^^^^
  File "/home/azureuser/MADS-ML-AdriaanS/.venv/lib/python3.11/site-packages/ray/tune/trainable/trainable.py", line 330, in train
    raise skipped from exception_cause(skipped)
  File "/home/azureuser/MADS-ML-AdriaanS/.venv/lib/python3.11/site-packages/ray/air/_internal/util.py", line 107, in run
    self._ret = self._target(*self._args, **self._kwargs)
                ^^^^^^^^^^^^^^^^^^^^^^^^^^^^^^^^^^^^^^^^^
  File "/home/azureuser/MADS-ML-AdriaanS/.venv/lib/python3.11/site-packages/ray/tune/trainable/function_trainable.py", line 45, in <lambda>
    training_func=lambda: self._trainable_func(self.config),
                          ^^^^^^^^^^^^^^^^^^^^^^^^^^^^^^^^^
           ^^^^^^^^^^^^^^^^^^^^^^^^^^^^^^^
  File "/home/azureuser/MADS-ML-AdriaanS/.venv/lib/python3.11/site-packages/ray/tune/trainable/function_trainable.py", line 261, in _trainable_func
    output = fn()
             ^^^^
  File "/home/azureuser/MADS-ML-AdriaanS/src/week_4/hypertuning.py", line 43, in train
    modelconfig = rnn_models.ModelConfig(**config)
                  ^^^^^^^^^^^^^^^^^^^^^^
AttributeError: module 'mltrainer.rnn_models' has no attribute 'ModelConfig'
